Workbook

Sheet 変更履歴
A1: PJ名 | C1: CBS構築プロジェクトSETP2 | W1: 成果物名 | Z1: 【CBS構築STEP2】個別テスト計画(GFP編)_性能テスト
V3: 変更履歴 | W3: (1/1)
A5: 履歴番号 | C5: 版数 | E5: 変更日 | H5: 区分 | J5: 変更箇所 | Q5: 変更内容 | AD5: 変更理由 | AL5: 担当者 | AO5: 承認者
A6: 001 | C6: 1.00 | E6: 2025/4/30 | H6: 新規 | J6: ファイル全体 | AD6: 新規作成 | AL6: TIS高野
A7: 002 | C7: 1.10 | E7: 2025/11/20 | H7: 修正 | J7: 2.1.1.共通ST（STEP1＋STEP2） | Q7: STEP2スケジュール変更に伴う共通ST実施の内容について変更 | AD7: STEP2スケジュール変更に伴い変更
Q8: STEP1での追加観点について記載 | AD8: 同上
J9: 2.1.2 STEP2単独 | Q9: STEP2単独性能テストに共通性能テストの残確認について追記 | AD9: 同上
J10: 2.2.基本方針 | Q10: MEBIUSのテスト計画に伴う記載修正 | AD10: 同上
J11: 2.3.前提/制約 | Q11: 前提について共通STについての内容を変更 | AD11: 同上
Q12: STEP2単独性能テストの資源について追記 | AD12: 同上
Q13: 制約として共通STの資源について追記 | AD13: 同上
J14: 2.4.開始終了基準 | Q14: 開始条件について追加 | AD14: 同上
J15: 3.1.1.実施範囲 | Q15: 実施環境について修正（GFPについては一部業務に制限） | AD15: 同上
Q16: FESについては不要のため除外 | AD16: 同上
Q17: CBSバッチ/CBSポータルについて環境名を修正 | AD17: 同上
J18: 3.1.2. 実施観点、実施対象 | Q18: GFP代行ケースについて、資源制限から共通STでは実施を中止 | AD18: 同上
Q19: STEP2側資源についての制限を記載。GFP代行除外についての理由説明。 | AD19: 同上
Q20: レスポンス時間については、まだ未確定の旨記載 | AD20: 同上
Q21: 限界値測定については、上限評価のみの実施とする旨記載。 | AD21: 同上
J22: 3.1.3. 実施方法 | Q22: バッチ・ポータルからの投入データ削除について依頼を記載 | AD22: 同上
J23: 3.1.3.2. データバリエーション | Q23: 投入するデータの作成方針について記載 | AD23: 同上
Q24: GFP投入データについて制限を記載 | AD24: 同上
Q25: 投入件数、仕向比率等全般的に見直し | AD25: 同上
J26: '3.1.4. 検証方法 | Q26: リソース確認対象について最新化 | AD26: 同上
Q27: バッチ・ポータルの検証内容についての記載を本書から削除 | AD27: 同上
J28: 3.1.5.ライブラリ(バージョン)管理 | Q28: ライブラリの考え方について記載 | AD28: 同上
J29: 3.1.6.合格条件 | Q29: ケース対象外を除外 | AD29: 同上
J30: 3.1.7.テスト環境 | Q30: 環境についての説明を追記 | AD30: 同上
Q31: 環境構成図を最新化 | AD31: 同上
J32: 3.2.1.実施範囲 | Q32: 共通STでの不足分を追加実施するため、DTPを実機利用に変更 | AD32: 同上
J33: 3.2.2. 実施観点、実施対象 | Q33: 共通ST残項目について説明を追記 | AD33: 同上
Q34: #2/#3について記載修正 | AD34: 同上
J35: 3.2.3.2. データバリエーション | Q35: 共通ST踏まえた投入データについての説明を追記 | AD35: 同上
J36: 3.2.4. 検証方法 | Q36: (2)システムリソース使用量について評価対象見直し | AD36: 同上
Q37: (3)スループットについて評価対象見直し | AD37: 同上
Q38: (6)取得情報について評価対象見直し | AD38: 同上
J39: 3.2.5.ライブラリ(バージョン)管理 | Q39: ライブラリの考え方について記載 | AD39: 同上
J40: 3.2.7.テスト環境 | Q40: 環境についての説明を追記 | AD40: 同上
Q41: 環境構成図を最新化 | AD41: 同上
J42: 3.2.8.ツール準備 | Q42: 対象ツールについて最新化 | AD42: 同上
...

Sheet 目次
A1: 成果物名 | C1: 【CBS構築STEP2】個別テスト計画(GFP編)_性能テスト | AB1: DBS番号 | AG1: 作成 | AH1: 45777 | AL1: TIS高野
A2: 管理番号 | C2: - | H2: 案件名称 | L2: CBS構築プロジェクトSTEP2 | AG2: 更新
B4: 【 目次 】
C6: 1. | D6: はじめに
D8: 1.1. | E8: 本書の位置付け
D9: 1.2. | E9: 本書の発行
D10: 1.3. | E10: 本書の見直し
C12: 2. | D12: テスト全体方針
D14: 2.1. | E14: テスト目的
D15: 2.2. | E15: 基本方針
D16: 2.3. | E16: 前提/制約
D17: 2.3.1. 前提事項
D18: 2.3.2. 制約事項
D19: 2.4. | E19: 開始終了基準
C21: 3. | D21: 実施概要
D23: 3.1. | E23: 共通ST
E24: 3.1.1.実施範囲
E25: 3.1.2. 実施観点、実施対象
E26: 3.1.3. 実施方法
E27: 3.1.4. 検証方法
E28: 3.1.5.ライブラリ(バージョン)管理
E29: 3.1.6.合格条件
E30: 3.1.7.テスト環境
E31: 3.1.8.ツール準備
E32: 実施観点、実施対象
E33: 実施方法
D35: 3.2. | E35: STEP2単独
E36: 3.2.1.実施範囲
E37: 3.2.2. 実施観点、実施対象
E38: 3.2.3. 実施方法
E39: 3.2.4. 検証方法
E40: 3.2.5.ライブラリ(バージョン)管理
E41: 3.2.6.合格条件
E42: 3.2.7.テスト環境
E43: 3.2.8.ツール準備
C45: 4. | D45: 各種管理
D47: 4.1. | E47: 進捗管理
D48: 4.2. | E48: 不具合管理
D49: 4.3. | E49: 品質管理
C51: 5. | D51: 詳細スケジュール/体制
...

Sheet 1.はじめに
A1: 成果物名 | C1: =目次!C1 -> 【CBS構築STEP2】個別テスト計画(GFP編)_性能テスト | AB1: DBS番号 | AG1: 作成 | AH1: =目次!AH1 -> 45777 | AL1: =目次!AL1 -> TIS高野
A2: 管理番号 | C2: - | H2: 案件名称 | L2: =目次!L2 -> CBS構築プロジェクトSTEP2 | AG2: 更新
B4: 1. はじめに
C6: 1.1. 本書の位置付け
D8: 株式会社ジェーシービー様（以下、JCB様と略す）向け「CBS構築プロジェクトSTEP2」における、個別テスト計画書（GFP編）_性能テスト計画を記述するものである。
Z40: < 本書 >
C61: 1.2. 本書の発行
D63: 本書の発行は、JCBと合意後、プロジェクトメンバーへの周知完了のタイミングを以って、完了とする。
C66: 1.3. 本書の見直し
D68: テスト方針、テストスケジュール等の変更が生じた場合には随時見直しを行い、本書の最適化・最新化を図る。
D69: また、実施手順作成のタイミングで見直しを行い、本書の最適化・最新化を図る。
D70: 本書の更新にあたっては、JCBとの合意を以って正式な更新とする。

Sheet 2.テスト全体方針
A1: 成果物名 | C1: =目次!C1 -> 【CBS構築STEP2】個別テスト計画(GFP編)_性能テスト | AB1: DBS番号 | AG1: 作成 | AH1: TIS | AL1: 45535
A2: 管理番号 | C2: - | H2: 案件名称 | L2: CBS構築プロジェクトSTEP2 | AG2: 更新
B4: 2.テスト全体方針
C6: 2.1.テスト目的
D8: 2.1.1.共通ST（STEP1＋STEP2）
E10: CBSを構築する全システム（FEP、FES、DTP、GFP、CBSバッチ、CBSポータル）の処理を稼働させ、以下内容を確認する。
E11: 本記載はGFPおよびFEP/FES/DTPを対象とし、CBSバッチ、CBSポータル側の目的の詳細については、各システムの個別テスト計画（性能テスト）を参照。
A12: 改版 | E12: ※ただし、GFPについては開発の遅延に伴い、一部の業務の完成に留まるため、該当業務のみに絞りテストを実施する。
A13: 改版 | E13: 全ての業務を利用しての性能確認については、STEP2単独テストでの確認とする。
E15: 目的① | G15: リソースの妥当性評価
G16: 2031年ピーク時間帯において、CPU負荷、メモリ使用量等、NSSのリソース使用量が性能要件を満たせるか確認する。
E18: 目的② | G18: トランザクション処理における消費コストの評価
G19: トランザクション処理（CBSポータルへのStriim連携、CBSポータル・CBSバッチからのAPI受信を含む）における消費コスト(スループット、処理レスポンス等)を確認する。
E21: 目的③ | G21: リソース・処理性能のボトルネック評価
G22: 限界値測定においてNSS内でボトルネックとなる箇所の有無を確認する。
A24: 改版 | E24: 目的④ | G24: STEP1観点の追加評価
A25: 改版 | G25: STEP1単独でのテストにおいて、基盤評価として過剰投入することでMQ制御スレッド不足が発生したが、本来の取引量においては解消することを確認する。
D27: 2.1.2 STEP2単独
E29: 平常時の取引処理に加えて、特異な状態が発生した場合の性能・リソース評価を行う。
E30: （J/BridgeからＧＦＰへの更改に伴い、大量データ処理に関する影響確認）
E32: 対象① | G32: 同一会員に対する取消が大量に発生した場合において、他のGFP取引への影響を確認する。
G34: （インプット） 2023/9/23 J/Bridge障害：想定外取消電文に伴うJ/Bridgeのオーソリ阻害
E36: 対象② | G36: 特定仕向からの大量データ（ネガデータ）が発生した場合において、他のGFP取引への影響を確認する。
G38: （インプット） 12_大量データ受信途上_セッション後_1031.xlsx
E40: 対象③ | G40: 特定被仕向からの大量データ（echo）が発生した場合において、他のGFP取引への影響を確認する。
G42: (インプット) 2024/2/12 J/Bridge障害：Adyenからの大量電文（echo電文）投入によるオーソリ利用阻害
E44: 対象④ | G44: 特定の仕向先ISSで応答遅延が発生した場合において、他のGFP取引への影響を確認する。
G46: (インプット） 2017/4/15 FEP障害：JCN障害 他
E48: 対象⑤ | G48: 大量データが発生した際に、国際NWのNW機器がボトルネックにならないことを確認する。
G50: (インプット） なし
A52: 改版 | E52: 対象⑥ | G52: 共通STでの実施残項目
A53: 改版 | G53: 共通STで実施残となる、GFP内の消費コスト確認、ボトルネック評価を実施する。
C55: 2.2.基本方針
D57: ＜全体＞
D59: ・ | E59: STEP1 + STEP2 の共通STとしての実施(CBS内のGFP/FEP/FES/DTPの全機能に負荷をかけた状態での実施)と、STEP2単独での実施、2つに分けて行う。
E60: 2種類のテストの実施により、「2031年ピーク時間帯」、「NSS限界値」、「特異な大量データ処理時」におけるリソース・性能評価を実施する。 | AU60: JCB#1
E62: 共通ST(STEP1 + STEP2) | J62: 新本番機を使用して、CBS(FEP/FES/DTP/GFP)全体の性能・リソース評価を行う。
E63: STEP2単独 | J63: 新検証機を使用して、平常時の取引処理に加えて、特異な状態が発生した場合の性能・リソース評価を行う。
D65: ・ | E65: 共通STは、テスト内容に応じて、新本番機（業務ノード）のCPUコアアップを実施して行う。ただし、新本番機（GWノード）のCPUコアアップは行わない。
E66: ※新本番機（GWノード）でCPUコアアップを行わなくて問題ないことは、STEP1で見極め済。詳細はSTEP1の「04-02-01要件定義書(非機能要件)」を参照。 | AU66: JCB#27
...

Sheet 3.1.共通ST
A1: 成果物名 | C1: =目次!C1 -> 【CBS構築STEP2】個別テスト計画(GFP編)_性能テスト | AB1: DBS番号 | AG1: 作成 | AH1: TIS | AL1: 45535
A2: 管理番号 | C2: - | H2: 案件名称 | L2: CBS構築プロジェクトSTEP2 | AG2: 更新
B4: 3.実施概要
C6: 3.1.共通ST
D8: 3.1.1.実施範囲
E10: テスト対象
E11: JCB内システム | V11: 海外NW | AC11: 国内NW | AK11: 海外加盟店/イシュア | AL11: 国内加盟店/イシュア | AM11: 運用
AM12: 基盤
E13: CBS | I13: CBSバッチ | J13: CBSポータル | K13: BRAIN | L13: STREAM | M13: BMS | N13: Redエンジン | O13: JENIUS | P13: PAR | Q13: DEEPS | R13: J-MARK | S13: I-MARK | T13: TAP/TMP | U13: J/Bridge | V13: J-Link | W13: NYCE | X13: DFS | Y13: VisaNet | Z13: BankNet | AA13: AEGN | AB13: UnionPay | AC13: CARDNET | AF13: CAFIS | AG13: SPSV | AH13: セブン銀行 | AI13: ATMOC | AJ13: J-TRANS | AM13: MEBIUS
E14: GFP | F14: FEP | G14: FES | H14: DTP | AC14: 1a | AD14: フル銀聯 | AE14: FEP接続
E21: ◎ | F21: ◎ | G21: ◎ | H21: ◎ | I21: ◎ | J21: ◎ | K21: - | L21: ○ | M21: - | N21: - | O21: ● | P21: - | Q21: ● | R21: - | S21: - | T21: ● | U21: - | V21: ● | W21: ● | X21: ● | Y21: ● | Z21: ● | AA21: ● | AB21: ● | AC21: ● | AD21: ● | AE21: ● | AF21: ● | AG21: ● | AH21: ● | AI21: ● | AJ21: - | AK21: ● | AL21: ● | AM21: 〇 | AV21: JCB#10
E24: 図. テスト範囲 | AE24: [ 凡例 ]
AF26: ◎ | AG26: ：参加（テスト観点あり）
AF27: ○ | AG27: ：参加（テスト観点なし）※テスト協力
AF28: ● | AG28: ：シミュレータ
Z38: [ 凡例 ]
AB40: テスト対象システム（確認観点あり）
AB41: テスト対象システム（確認観点なし）
AB42: シミュレータとする接続先
E46: ○実施環境(CBS)
P47: 構築対象 | T47: 接続有無
E48: 分類 | H48: ノード | P48: GFP | Q48: FEP | R48: FES | S48: DTP | T48: 東阪接続 | V48: CBSバッチ | X48: CBSポータル | Z48: JCB内 | AB48: 外部接続 | AD48: 運用/基盤 | AF48: 本番差異 | AH48: 概要
Z49: (※1) | AB49: (※2) | AD49: (※3)
E50: 新本番機 | H50: 東京 | J50: 先行開発環境 | P50: ○ | Q50: - | R50: - | S50: - | T50: - | V50: - | X50: - | Z50: - | AB50: - | AD50: - | AF50: -
H51: 大阪
A52: 改版 | J52: 本番昇格環境 | P52: ○※ | Q52: ○ | R52: ○ | S52: ○ | T52: ○ | V52: ○ | X52: ○ | Z52: - | AB52: - | AD52: - | AF52: なし※ | AH52: リリース後、本番稼働する環境。
A53: 改版 | AH53: ※GFPについては一部業務のみ
E54: 新検証機 | H54: 東京 | J54: 開発環境 | M54: 単体テスト環境 | P54: ○ | Q54: ○ | R54: - | S54: ○ | T54: - | V54: - | X54: - | Z54: - | AB54: - | AD54: - | AF54: -
M56: 結合テスト環境 | P56: ○ | Q56: ○ | R56: ○ | S56: ○ | T56: - | V56: - | X56: - | Z56: - | AB56: - | AD56: - | AF56: -
M58: システムテスト | P58: ○ | Q58: - | R58: - | S58: - | T58: - | V58: - | X58: - | Z58: - | AB58: - | AD58: - | AF58: -
M59: 環境
M60: 保守追い付き | P60: ○ | Q60: ○ | R60: - | S60: ○ | T60: - | V60: - | X60: - | Z60: - | AB60: - | AD60: - | AF60: -
M61: 環境
M62: 不具合取り込み | P62: ○ | Q62: ○ | R62: - | S62: ○ | T62: - | V62: - | X62: - | Z62: - | AB62: - | AD62: - | AF62: -
M63: 環境
M64: 並行テスト環境 | P64: ○ | Q64: ○ | R64: ○ | S64: ○ | T64: - | V64: - | X64: - | Z64: - | AB64: - | AD64: - | AF64: -
M66: ST取引投入 | P66: ○ | Q66: ○ | R66: ○ | S66: ○ | T66: ○ | V66: - | X66: - | Z66: - | AB66: - | AD66: - | AF66: あり(※4) | AH66: 取引を投入するための環境(新大阪本番機向け)
M67: 環境 | AH67: 業務影響はないので本番差異があっても問題なし。
J68: 本番相当環境 | P68: ○ | Q68: ○ | R68: ○ | S68: ○ | T68: - | V68: - | X68: - | Z68: - | AB68: - | AD68: - | AF68: -
E70: 現行検証機 | H70: 東京 | J70: 開発環境 | M70: ST取引投入 | P70: ○ | Q70: ○ | R70: ○ | S70: ○ | T70: ○ | V70: - | X70: - | Z70: - | AB70: - | AD70: - | AF70: あり(※4) | AH70: 取引を投入するための環境(新東京本番機向け)
...

Sheet 3.2.STEP2単独
A1: 成果物名 | C1: =目次!C1 -> 【CBS構築STEP2】個別テスト計画(GFP編)_性能テスト | AB1: DBS番号 | AG1: 作成 | AH1: TIS | AL1: 45535
A2: 管理番号 | C2: - | H2: 案件名称 | L2: CBS構築プロジェクトSTEP2 | AG2: 更新
B4: 3.実施概要
C6: 3.2.STEP2単独
D8: 3.2.1.実施範囲
E10: テスト対象
E11: JCB内システム | V11: 海外NW | AC11: 国内NW | AK11: 海外加盟店/イシュア | AL11: 国内加盟店/イシュア
E12: CBS | I12: CBSバッチ | J12: CBSポータル | K12: BRAIN | L12: STREAM | M12: BMS | N12: Redエンジン | O12: JENIUS | P12: PAR | Q12: DEEPS | R12: J-MARK | S12: I-MARK | T12: TAP/TMP | U12: J/Bridge | V12: J-Link | W12: NYCE | X12: DFS | Y12: VisaNet | Z12: BankNet | AA12: AEGN | AB12: UnionPay | AC12: CARDNET | AF12: CAFIS | AG12: SPSV | AH12: セブン銀行 | AI12: ATMOC | AJ12: J-TRANS
E13: GFP | F13: FEP | G13: FES | H13: DTP | AC13: 1a | AD13: フル銀聯 | AE13: FEP接続
A20: 改版 | E20: ◎ | F20: ○ | G20: ● | H20: ○ | I20: - | J20: ○ | K20: - | L20: - | M20: - | N20: - | O20: ● | P20: - | Q20: - | R20: - | S20: - | T20: - | U20: - | V20: ● | W20: ● | X20: ● | Y20: ● | Z20: ● | AA20: ● | AB20: ● | AC20: ● | AD20: ● | AE20: ● | AF20: ● | AG20: ● | AH20: - | AI20: - | AJ20: - | AK20: ● | AL20: ● | AV20: JCB#3
E22: 図. テスト範囲 | AE22: [ 凡例 ]
AF24: ◎ | AG24: ：参加（テスト観点あり）
AF25: ○ | AG25: ：参加（テスト観点なし）※テスト協力
AF26: ● | AG26: ：シミュレータ
Z36: [ 凡例 ] | AV36: JCB#18
AB38: テスト対象システム（確認観点あり）
AB39: テスト対象システム（確認観点なし）
AB40: シミュレータとする接続先
E44: ○実施環境(CBS)
P45: 構築対象 | T45: 接続有無
E46: 分類 | H46: ノード | P46: GFP | Q46: FEP | R46: FES | S46: DTP | T46: 東阪接続 | V46: CBSバッチ | X46: CBSポータル | Z46: JCB内 | AB46: 外部接続 | AD46: 運用/基盤 | AF46: 本番差異 | AH46: 概要
Z47: (※1) | AB47: (※2) | AD47: (※3)
E48: 新本番機 | H48: 東京 | J48: 先行開発環境 | P48: ○ | Q48: - | R48: - | S48: - | T48: - | V48: - | X48: - | Z48: - | AB48: - | AD48: - | AF48: -
H49: 大阪
J50: 本番昇格環境 | P50: ○ | Q50: ○ | R50: ○ | S50: ○ | T50: ○ | V50: ○ | X50: ○ | Z50: ○ | AB50: ○ | AD50: ○ | AF50: なし
E52: 新検証機 | H52: 東京 | J52: 開発環境 | M52: 単体テスト環境 | P52: ○ | Q52: ○ | R52: - | S52: ○ | T52: - | V52: - | X52: - | Z52: - | AB52: - | AD52: - | AF52: -
M54: 結合テスト環境 | P54: ○ | Q54: ○ | R54: ○ | S54: ○ | T54: - | V54: - | X54: - | Z54: - | AB54: - | AD54: - | AF54: -
M56: システムテスト | P56: ○ | Q56: - | R56: - | S56: - | T56: - | V56: - | X56: - | Z56: - | AB56: - | AD56: - | AF56: -
M57: 環境
M58: 保守追い付き | P58: ○ | Q58: ○ | R58: - | S58: ○ | T58: - | V58: - | X58: - | Z58: - | AB58: - | AD58: - | AF58: -
M59: 環境
M60: 不具合取り込み | P60: ○ | Q60: ○ | R60: - | S60: ○ | T60: - | V60: - | X60: - | Z60: - | AB60: - | AD60: - | AF60: -
M61: 環境
M62: 並行テスト環境 | P62: ○ | Q62: ○ | R62: ○ | S62: ○ | T62: - | V62: - | X62: - | Z62: - | AB62: - | AD62: - | AF62: -
M64: ST取引投入 | P64: ○ | Q64: ○ | R64: ○ | S64: ○ | T64: ○ | V64: - | X64: - | Z64: - | AB64: - | AD64: - | AF64: -
M65: 環境
J66: 本番相当環境 | P66: ○ | Q66: ○ | R66: ○ | S66: ○ | T66: - | V66: - | X66: - | Z66: - | AB66: - | AD66: - | AF66: あり(※4)
E68: 現行検証機 | H68: 東京 | J68: 開発環境 | M68: ST取引投入 | P68: ○ | Q68: ○ | R68: ○ | S68: ○ | T68: ○ | V68: - | X68: - | Z68: - | AB68: - | AD68: - | AF68: -
M69: 環境
E70: ※1 ： BRAIN、BMS、Redエンジン、I-MARK、J/Bridge
...

Sheet 4.5.6.
A1: 成果物名 | C1: =目次!C1 -> 【CBS構築STEP2】個別テスト計画(GFP編)_性能テスト | AB1: DBS番号 | AG1: 作成 | AH1: TIS | AL1: 45535
A2: 管理番号 | C2: - | H2: 案件名称 | L2: CBS構築プロジェクトSTEP2 | AG2: 更新
B4: 4.各種管理
C5: 4.1. 進捗管理
D7: 「全体テスト計画書(共通編) 6. テスト運営」を参照。 | AN7: JCB_#40
C9: 4.2. 不具合管理
D11: 「全体テスト計画書(共通編) 6. テスト運営」を参照。 | AN11: JCB_#40
C13: 4.3. 品質管理
D15: 「全体テスト計画書(共通編) 6. テスト運営」を参照。 | AN15: JCB_#40
C18: 5.詳細スケジュール/体制
D20: 5.1.スケジュール
A21: 改版 | D21: 別紙2.中日程参照
D23: 5.2. 体制
A24: 改版 | E24: < 共通ST >
A25: 改版 | E25: No | F25: 役割 | K25: 内容 | U25: 役割
A26: 改版 | W26: JCB | AB26: STEP1 | AE26: GFP | AH26: ポータル | AK26: バッチ
A27: 改版 | E27: 1 | F27: テスト統括 | K27: ST全体の検討・推進・とりまとめ・品質管理・進捗管理と | U27: リーダ | W27: 関戸（・佐藤） | AB27: ― | AE27: 稲垣（・内藤・平井） | AK27: 村田（・古里）
A28: 改版 | K28: いったテスト運営。個別テスト統括から全体へ派生する | U28: PMO | W28: 佐藤（・他調整中） | AE28: 宍戸・堀 | AK28: 新井・黒岩
A29: 改版 | K29: 影響や調整事項の実施
A30: 改版 | E30: 2 | F30: テストリーダ（インフラ） | K30: インフラ視点のST（性能・障害・運用・サイクル）の検討・ | U30: 本体 | W30: 関戸（・西） | AB30: ― | AE30: 内藤 | AH30: 間淵 | AK30: 古里
A31: 改版 | K31: 推進・とりまとめから、性能テストへの調整、監督 | U31: ポータル | W31: 飯野
A32: 改版 | U32: バッチ | W32: 大場
A33: 改版 | E33: 3 | F33: 性能テスト担当 | K33: 性能テストリーダー、JCBおよび関連チーム | U33: 本体 | W33: 関戸・(若曽根・西) | AB33: 内藤・山本（和） (久保田) | AH33: 秋山・間淵 | AK33: 古里・小林・山口
A34: 改版 | K34: （バッチ・ポータル）との窓口 | U34: ポータル | W34: 蒔田・是枝
A35: 改版 | U35: バッチ | W35: 蒔田(インフラ)・XX（アプリ）
A36: 改版 | E36: 4 | F36: 準備担当 | K36: テスト準備の担当
A37: 改版 | L37: 計画・ケース作成 | AB37: 1名
A38: 改版 | L38: 環境作成 | AB38: 計3名 | AE38: 環境構築T
A39: 改版 | L39: ツール整備 | AE39: ツールT
A40: 改版 | L40: データ作成 | AE40: ツールT
A41: 改版 | L41: マスタ作成 | AE41: マスタT
A42: 改版 | M42: 移行データ | AE42: 移行T
A43: 改版 | M43: 書出しデータ | AE43: 仕様統括
A44: 改版 | M44: ITBデータ移行 | AE44: マスタT
A45: 改版
A46: 改版 | E46: 5 | F46: 実施担当 | K46: テスト実施担当
A47: 改版 | L47: データ投入 | AE47: 3名
A48: 改版 | L48: 調査・対応 | AE48: 3名
A49: 改版 | L49: 分析・評価 | AE49: 3名
A50: 改版 | L50: 結果報告作成 | AE50: 2名
...

Sheet 別紙1.CBS環境差異
A2: 別紙1.CBS環境差異
B4: ✔ マシンスペックにより構築できるアプリケーション環境に差異がある為、マシンスペックの本番差異を記載する。
B5: ✔ 各テスト工程で実施する環境を選定する為、アプリケーション環境の本番差異を記載する。
B8: 表.CBS HW構成差分 | F8: ※赤太字部分は本番差異あり
C9: 東京本番 | D9: 大阪本番 | E9: 東京検証 | F9: 大阪検証
B10: 設置場所 | C10: GDC御殿山 | D10: 心斎橋gDC-EX | E10: GDC御殿山 | F10: 心斎橋gDC-EX
B11: 機種 | C11: HPE NonStop NS8 | D11: HPE NonStop NS8 | E11: HPE NonStop NS8 | F11: HPE NonStop NS4
B12: CPU数 | C12: 8CPU | D12: 8CPU | E12: 8CPU | F12: 4CPU
B13: コア数 | C13: 2コア+従量課金 | D13: 2コア+従量課金 | E13: 2コア+NSDC | F13: 1コア
B14: 従量課金ライセンス | C14: Flexible Core License | D14: Flexible Core License | E14: NSDC 30日/年 | F14: 無し
B15: メモリーサイズ | C15: 128GB/CPU | D15: 128GB/CPU | E15: 128GB/CPU | F15: 64GB/CPU
B16: IP CLIM数 | C16: 4C/1Cタイプ： 13台 | D16: 4C/1Cタイプ： 13台 | E16: 4C/1Cタイプ： 13台 | F16: 4C/1Cタイプ： 4台
C17: 4F/1Cタイプ： 2台 | D17: 4F/1Cタイプ： 2台 | E17: 4F/1Cタイプ： 2台
B18: Storage CLIM数 | C18: 8台 | D18: 8台 | E18: 8台 | F18: 4台
B19: 内蔵DISK本数 | C19: 1.6TB SSDx6本（最小本数） | D19: 1.6TB SSDx6本（最小） | E19: 1.6TB SSDx6本（最小） | F19: 1.6TB SSDx100本
B20: DISKタイプ | C20: 内蔵DISK、XP8ともSSD | D20: 内蔵DISK、XP8ともSSD | E20: 内蔵DISK、XP8ともSSD | F20: 内蔵SSD
B21: XP8 台数 | C21: 1台 | D21: 1台 | E21: 筐体のみ東京本番と共有 | F21: 無し
B22: XP8 DISK容量 | C22: 20.6TB(初期導入時) | D22: 20.6TB(初期導入時) | E22: 20.6TB(初期導入時) | F22: 無し
B23: バックアップ装置 | C23: LTO8×1、VTR 16TB×2 | D23: LTO8×1、VTR 16TB×2 | E23: LTO8×1、VTR 16TB×1 | F23: LTO8×1、VTR 16TB×1
B24: ラック数 | C24: 3台 | D24: 3台 | E24: 3台 | F24: 2台
B25: ATALLA | C25: 10000TPSライセンス×3 | D25: 10000TPSライセンス×3 | E25: 10000TPSライセンス×3 | F25: 1080TPSライセンス×2
C26: 1080TPSライセンス×2 | D26: 1080TPSライセンス×2 | E26: 1080TPSライセンス×2
B27: 3rd P製品 | C27: CSP PassPort、HULFT | D27: CSP PassPort、HULFT | E27: CSP PassPort、HULFT | F27: CSP PassPort、HULFT
B30: 表.CBS アプリケーション環境構成差分
C31: 東京本番 | D31: 大阪本番 | E31: 東京検証 | F31: 大阪検証
B32: 本番昇格環境 | C32: - | D32: - | E32: - | F32: -
B33: 単体テスト環境 | C33: 本番機への構築なし | D33: 本番機への構築なし | E33: ■起動情報 起動ユーザの差異あり。 ■プロセス 稼働数が少ない、稼働CPUが異なる等の差異あり。 ■ファイル 配置、サイズが小さい等の差異あり。 ■東阪稼働状態 東京/大阪、いずれかのみの稼働で東阪接続なし。 | F33: ■起動情報 起動ユーザの差異あり。 ■プロセス 稼働数が少ない、稼働CPUが異なる等の差異あり。 ■ファイル 配置、サイズが小さい等の差異あり。 ■東阪稼働状態 東京/大阪、いずれかのみの稼働で東阪接続なし。
B34: 結合テスト環境 | C34: 本番機への構築なし | D34: 本番機への構築なし | E34: ■起動情報 起動ユーザの差異あり。 ■プロセス 稼働数が少ない、稼働CPUが異なる等の差異あり。 ■ファイル 配置、サイズが小さい等の差異あり。 ■東阪稼働状態 東京/大阪、接続した環境を構築。 | F34: ■起動情報 起動ユーザの差異あり。 ■プロセス 稼働数が少ない、稼働CPUが異なる等の差異あり。 ■ファイル 配置、サイズが小さい等の差異あり。 ■東阪稼働状態 東京/大阪、接続した環境を構築。
B35: システムテスト環境 | C35: 本番機への構築なし | D35: 本番機への構築なし | E35: 同上 | F35: 同上
B36: 保守追い付き環境 | C36: 本番機への構築なし | D36: 本番機への構築なし | E36: 同上 | F36: 同上
B37: 不具合取り込み環境 | C37: 本番機への構築なし | D37: 本番機への構築なし | E37: 同上 | F37: 同上
B38: 本番相当環境 | C38: 本番機への構築なし | D38: 本番機への構築なし | E38: ■起動情報 差異なし。 ■プロセス 差異なし。 ■ファイル 差異なし。 | F38: ■起動情報 差異なし。 ■プロセス 差異なし。 ■ファイル 差異なし。

Sheet 別紙2.中日程
A2: 性能テスト_スケジュール（中日程） | D2: 時点：
B4: 大分類 | C4: 中分類 | D4: seq | E4: 小分類 | F4: 補足 | G4: 対応不要理由 | H4: Todo・課題 | I4: 予備 | J4: 主担当 | K4: 後続タスク | L4: ステータス | M4: 進捗状況 | Q4: 10月 | U4: 11月 | Y4: 12月 | AD4: 1月 | AH4: 2月 | AL4: 3月 | AQ4: 4月 | AU4: 5月 | AY4: 6月 | BD4: 7月 | BH4: 8月 | BM4: ９月
G5: 対応時、中間成果物名 | H5: No記載 | J5: （タスク管理者） | M5: 単位 | N5: 総数 | O5: 実績 | P5: 遅延有無 | Q5: 45936 | R5: =Q5+7 -> 45943 | S5: =R5+7 -> 45950 | T5: =S5+7 -> 45957 | U5: =T5+7 -> 45964 | V5: =U5+7 -> 45971 | W5: =V5+7 -> 45978 | X5: =W5+7 -> 45985 | Y5: =X5+7 -> 45992 | ... BP5: =BO5+7 -> 46293
B6: イベント | AC6: ▼結合テスト-Exit | BL6: ▼システムテスト-Exit
C7: ▼赤字:クライテリア | AC7: ▼システムテストEntry | BL7: ▼移行展開Entry
C8: ▽青字:主要マイルストーン
AH10: ▽STEP1/2合流（性能T、サイクルT、業務シナリオT）
AL11: ▽Ita終了後： 運用T、ブランド認定T疎通、業務シナリオT および 全体移行リハ①
T12: ▽通信制御（NYCE/UnionPay）開発完了 | AQ12: ▽Itb終了後： 運用T、J-Link先事前疎通～試験、並行T、サイクルT
AY14: ▽全体移行リハ②
B18: 共通性能 | C18: 課題・ToDo対応 | D18: 1 | E18: ライブラリ管理反映（ToDo#101） | H18: ToDo#101 | J18: TIS | L18: 完了
B19: 準備 | D19: 2 | E19: 投入件数見直し（ToDo#110） | F19: GFP投入件数見直し | H19: ToDo#110 | J19: TIS | K19: 18、19
D20: 3 | F20: トークン比率設定 | H20: ToDo#110 | J20: JCB | K20: 18、19
D21: 4 | F21: 代行件数比率設定 | G21: 単独性能テストに向けて | H21: ToDo#110 | J21: JCB
D22: 5 | F22: バッチ処理件数設定 | H22: ToDo#110 | J22: TIS | K22: 18、19
D23: 6 | E23: シナリオ要件反映（ToDo#126） | F23: ネガデータ投入件数設定 | G23: 単独性能テストに向けて | H23: ToDo#126 | J23: TIS
D24: 7 | F24: エコー電文投入件数設定 | G24: 単独性能テストに向けて | H24: ToDo#126 | J24: TIS
D25: 8 | F25: 全件タイムアウトISS決定 | G25: 単独性能テストに向けて | H25: ToDo#126 | J25: JCB
D26: 9 | F26: 全件タイムアウトISS投入量決定 | G26: 単独性能テストに向けて | H26: ToDo#126 | J26: JCB
D27: 10 | E27: 回線帯域確認 | G27: 単独性能テストに向けて | J27: IBM
C28: 計画修正 | D28: 11 | E28: 計画書修正 | J28: TIS | X28: ★
C29: ケース作成 | D29: 12 | E29: ケース作成 | J29: TIS
C30: 環境作成 | D30: 13 | E30: 検討 | J30: 環境T | K30: 23
D31: 14 | E31: 環境定義作成 | J31: 環境T | K31: 23
D32: 15 | E32: 環境作成 | J32: 環境T | K32: 23
C33: ツール整備 | D33: 16 | E33: 投入ツール作成（修正） | J33: ツールT | K33: 23
D34: 17 | E34: 応答ツール作成（修正） | J34: ツールT | K34: 23
C35: データ作成 | D35: 18 | E35: 投入データ作成 | J35: TIS | K35: 23
D36: 19 | E36: 応答データ作成 | J36: TIS | K36: 23
C37: マスタ作成 | D37: 20 | E37: 移行データ | J37: 移行T | K37: 23
D38: 21 | E38: 書出し | J38: 仕様統括 | K38: 23
D39: 22 | E39: ITB移行 | J39: マスタT | K39: 23
C40: 環境疎通 | D40: 23 | E40: 疎通確認 | J40: TIS | K40: 24
C41: 事前検証 | D41: 24 | E41: 実施・確認（TPSのみ） | J41: TIS | K41: 25
D42: 25 | E42: 修正・チューニング | J42: TIS | K42: 26
D43: 26 | E43: 実施・確認（TPSのみ）（再） | J43: TIS | K43: 27
B44: 共通性能 | C44: 実施 | D44: 27 | E44: 実施・検証 | J44: TIS | K44: 28
B45: 実施 | D45: 28 | E45: 分析 | J45: TIS | K45: 29
D46: 29 | E46: 修正・チューニング | J46: TIS | K46: 30
D47: 30 | E47: 実施・検証（予備） | J47: TIS | K47: 31
...

Sheet 【カメラ】俯瞰図_共通ST

Sheet 【カメラ】テスト環境図
X114: ：確認I/F | AB114: ：接続I/F | AF114: ：テスト用環境 | AK114: ：未使用

Sheet 【カメラ】テスト環境図 (単独)

Sheet カメラ (2)
A1: 成果物名 | C1: 全体テスト計画書 | AC1: DBS番号 | AH1: 作成 | AI1: TIS後藤 | AM1: 43770
A2: 管理番号 | C2: - | F2: 案件名称 | H2: FEP更改プロジェクト | AH2: 更新
D5: ＜テスト実施スケジュール＞
D6: 実施項目 | P6: 2020年
P7: 44105 | Z7: 44136 | AU7: =EDATE(Z7,1) -> 44166
P8: 19 | Q8: =P8+1 -> 20 | R8: =Q8+1 -> 21 | S8: =R8+1 -> 22 | T8: =S8+1 -> 23 | U8: =T8+3 -> 26 | V8: =U8+1 -> 27 | W8: =V8+1 -> 28 | X8: =W8+1 -> 29 | Y8: =X8+1 -> 30 | Z8: 2 | AA8: =Z8+1 -> 3 | AB8: =AA8+1 -> 4 | AC8: =AB8+1 -> 5 | AD8: =AC8+1 -> 6 | AE8: =AD8+3 -> 9 | AF8: =AE8+1 -> 10 | AG8: =AF8+1 -> 11 | AH8: =AG8+1 -> 12 | AI8: =AH8+1 -> 13 | AJ8: =AI8+3 -> 16 | AK8: =AJ8+1 -> 17 | AL8: =AK8+1 -> 18 | AM8: =AL8+1 -> 19 | AN8: =AM8+1 -> 20 | AO8: =AN8+3 -> 23 | AP8: =AO8+1 -> 24 | AQ8: =AP8+1 -> 25 | AR8: =AQ8+1 -> 26 | AS8: =AR8+1 -> 27 | AT8: =AS8+3 -> 30 | AU8: 1 | AV8: =AU8+1 -> 2 | AW8: =AV8+1 -> 3 | AX8: =AW8+1 -> 4
D9: ①接続確認
E10: JENIUS
E11: DEEPS
E12: TAP/BRAIN
D13: ②業務機能確認
E14: JENIUS | G14: MQ | I14: 被仕向 | K14: 現環境 | M14: 20
K15: 新環境 | M15: 20
I16: 仕向 | K16: 現環境 | M16: 21
K17: 新環境 | M17: 21
G18: HULFT | I18: 集信 | K18: 現環境 | M18: 20
K19: 新環境 | M19: 20
I20: 配信 | K20: 現環境 | M20: 20
K21: 新環境 | M21: 20
E22: DEEPS | G22: MQ | I22: 被仕向 | K22: 現環境 | M22: 7
K23: 新環境 | M23: 7
I24: 仕向 | K24: 現環境 | M24: 9
K25: 新環境 | M25: 9
G26: HULFT | I26: 被仕向 | K26: 現環境 | M26: 3
K27: 新環境 | M27: 3
I28: 仕向 | K28: 現環境 | M28: 11
K29: 新環境 | M29: 11
E30: TAP | G30: MQ | I30: 被仕向 | K30: 現環境 | M30: 30
K31: 新環境 | M31: 30
I32: 仕向 | K32: 現環境 | M32: 29
K33: 新環境 | M33: 29
G34: HULFT | I34: 被仕向 | K34: 現環境 | M34: 1
K35: 新環境 | M35: 1
I36: 仕向 | K36: 現環境 | M36: 7
K37: 新環境 | M37: 7
E38: BRAIN | G38: HULFT | I38: 配信 | K38: 現環境 | M38: 1
K39: 新環境 | M39: 1
D41: 【凡例】 | H41: ：予定期間
H42: ：予備期間
